Workbook

Sheet Analysis
B2: Analysis Date | E2: =TODAY() -> 46176 | G2: Operating Income | R2: Unit Mix
B3: Analysis By | E3: T. Perun | G3: Income | H3: Trailing 12 | I3: $/Unit | J3: % | K3: Marketing | L3: $/Unit | M3: % | N3: Marketing | O3: $/Unit | P3: % | S3: Unit Type | T3: # of Units | U3: SF | V3: Current Rent | W3: High Achieved Rent | X3: Pro Forma
B4: Property Information | G4: Gross Potential Rent | H4: =$X$11 -> 306108 | K4: =$X$11 -> 306108 | N4: =$X$11 -> 306108 | S4: 2/1.00 | T4: =IF(S4="*Insert Unit Type*","",COUNTIF($T$16:$T$24,S4)) -> 1 | U4: =IFERROR(AVERAGEIF($T$16:$T$24,S4,$U$16:$U$24),"") -> 950 | V4: =IF(S4="*Insert Unit Type*","",(AVERAGEIF($T$16:$T$24,S4,$V$16:$V$24))) -> 2875 | W4: =IF(S4="*Insert Unit Type*","",_xlfn.MAXIFS($V$16:$V$24,$T$16:$T$24,S4)) -> 2875 | X4: 3100
B5: Property Name | E5: 613 Main Street | G5: Below Market Rent | H5: =H6-H4 -> -31476 | J5: =IFERROR(H5/H6,0) -> -0.11461155 | K5: =K6-K4 -> -31476 | M5: =IFERROR(K5/K6,0) -> -0.11461155 | N5: =N6-N4 -> 0 | P5: =IFERROR(N5/N6,0) -> 0 | S5: 2/1.00 - 60% | T5: =IF(S5="*Insert Unit Type*","",COUNTIF($T$16:$T$24,S5)) -> 1 | U5: =IFERROR(AVERAGEIF($T$16:$T$24,S5,$U$16:$U$24),"") -> 650 | V5: =IF(S5="*Insert Unit Type*","",(AVERAGEIF($T$16:$T$24,S5,$V$16:$V$24))) -> 1534 | W5: =IF(S5="*Insert Unit Type*","",_xlfn.MAXIFS($V$16:$V$24,$T$16:$T$24,S5)) -> 1534 | X5: 1935
B6: Address | E6: 613 Main Street | G6: Gross Scheduled Rent | H6: =$V$11 -> 274632 | K6: =$V$11 -> 274632 | N6: =$X$11 -> 306108 | S6: 2/1.50 | T6: =IF(S6="*Insert Unit Type*","",COUNTIF($T$16:$T$24,S6)) -> 1 | U6: =IFERROR(AVERAGEIF($T$16:$T$24,S6,$U$16:$U$24),"") -> 850 | V6: =IF(S6="*Insert Unit Type*","",(AVERAGEIF($T$16:$T$24,S6,$V$16:$V$24))) -> 2995 | W6: =IF(S6="*Insert Unit Type*","",_xlfn.MAXIFS($V$16:$V$24,$T$16:$T$24,S6)) -> 2995 | X6: 3200
B7: City/State/Zip | E7: Ridgefield, CT, 06877 | G7: Vacancy & Collections Loss | H7: =-ABS(J7*H6) -> 0 | J7: 0 | K7: =-ABS(K6*M7) -> -5492.64 | M7: 0.02 | N7: =-ABS(N6*P7) -> -6122.16 | P7: 0.02 | S7: 2/1.5 TH w. Basement - 60% | T7: =IF(S7="*Insert Unit Type*","",COUNTIF($T$16:$T$24,S7)) -> 1 | U7: =IFERROR(AVERAGEIF($T$16:$T$24,S7,$U$16:$U$24),"") -> 1052 | V7: =IF(S7="*Insert Unit Type*","",(AVERAGEIF($T$16:$T$24,S7,$V$16:$V$24))) -> 1478 | W7: =IF(S7="*Insert Unit Type*","",_xlfn.MAXIFS($V$16:$V$24,$T$16:$T$24,S7)) -> 1478 | X7: 1935
B8: Year Built | E8: 2012 | G8: Effective Rental Income | H8: =V25*12 -> 274632 | K8: =SUM(K6:K7) -> 269139.36 | N8: =SUM(N6:N7) -> 299985.84 | S8: 2/1.5 TH w. Basement - 80% | T8: =IF(S8="*Insert Unit Type*","",COUNTIF($T$16:$T$24,S8)) -> 1 | U8: =IFERROR(AVERAGEIF($T$16:$T$24,S8,$U$16:$U$24),"") -> 1052 | V8: =IF(S8="*Insert Unit Type*","",(AVERAGEIF($T$16:$T$24,S8,$V$16:$V$24))) -> 2039 | W8: =IF(S8="*Insert Unit Type*","",_xlfn.MAXIFS($V$16:$V$24,$T$16:$T$24,S8)) -> 2039 | X8: 2039
B9: Building SF | E9: 9900 | G9: Utility Bill Back | H9: =765*12 -> 9180 | I9: =IFERROR(H9/$E$11,0) -> 1020 | K9: =H9 -> 9180 | L9: =IFERROR(K9/$E$11,0) -> 1020 | N9: =K9 -> 9180 | O9: =IFERROR(N9/$E$11,0) -> 1020 | S9: 2/1.5 TH w. Basement | T9: =IF(S9="*Insert Unit Type*","",COUNTIF($T$16:$T$24,S9)) -> 1 | U9: =IFERROR(AVERAGEIF($T$16:$T$24,S9,$U$16:$U$24),"") -> 1052 | V9: =IF(S9="*Insert Unit Type*","",(AVERAGEIF($T$16:$T$24,S9,$V$16:$V$24))) -> 2825 | W9: =IF(S9="*Insert Unit Type*","",_xlfn.MAXIFS($V$16:$V$24,$T$16:$T$24,S9)) -> 2825 | X9: 3250
B10: Rentable SF | E10: =SUM(U16:U24) -> 8762 | G10: Total Additional Income | H10: =SUM(H9:H9) -> 9180 | I10: =SUM(I9:I9) -> 1020 | K10: =SUM(K9:K9) -> 9180 | L10: =SUM(L9:L9) -> 1020 | N10: =SUM(N9:N9) -> 9180 | O10: =SUM(O9:O9) -> 1020 | S10: 2/1.5 TH w. Garage | T10: =IF(S10="*Insert Unit Type*","",COUNTIF($T$16:$T$24,S10)) -> 3 | U10: =IFERROR(AVERAGEIF($T$16:$T$24,S10,$U$16:$U$24),"") -> 1052 | V10: =IF(S10="*Insert Unit Type*","",(AVERAGEIF($T$16:$T$24,S10,$V$16:$V$24))) -> 3046.6667 | W10: =IF(S10="*Insert Unit Type*","",_xlfn.MAXIFS($V$16:$V$24,$T$16:$T$24,S10)) -> 3350 | X10: 3350
B11: Units | E11: =T11 -> 9 | R11: Annual Total | T11: =SUM(T4:T10) -> 9 | V11: =SUMPRODUCT($T$4:$T$10,V4:V10)*12 -> 274632 | W11: =SUMPRODUCT($T$4:$T$10,W4:W10)*12 -> 285552 | X11: =SUMPRODUCT($T$4:$T$10,X4:X10)*12 -> 306108
B12: Lot Size (Acres) | E12: 0.5 | G12: Effective Gross Income | H12: =IFERROR(H8+H10,0) -> 283812 | K12: =K8+K10 -> 278319.36 | N12: =N8+N10 -> 309165.84 | R12: Average | U12: =IFERROR(AVERAGE(U16:U24),0) -> 973.55556 | V12: =IFERROR(AVERAGE(V16:V24),0) -> 2542.8889 | W12: =IFERROR(AVERAGE(W16:W24),0) -> 2644 | X12: =IFERROR(AVERAGE(X16:X24),0) -> 2834.3333
B13: Investment Information
B14: Purchase Price | E14: 3600000 | G14: Operating Expense | R14: Rent Roll
B15: Price/Unit | E15: =IFERROR(E14/E11,0) -> 400000 | G15: Expense | H15: Trailing 12 | I15: $/Unit | J15: % | K15: =K3 -> Marketing | L15: $/Unit | M15: % | N15: =N3 -> Marketing | O15: $/Unit | P15: % | R15: Property | S15: Unit # | T15: Unit Type | U15: SF | V15: Current Rent | W15: High Achieved Rent | X15: Pro Forma | Y15: Lease Start | Z15: Lease End
B16: Price/SF | E16: =E14/E9 -> 363.63636 | G16: Real Estate Tax | H16: ='Tax Analysis'!D14 -> 27743.32 | I16: =IFERROR(H16/$E$11,0) -> 3082.5911 | K16: =H16 -> 27743.32 | L16: =IFERROR(K16/$E$11,0) -> 3082.5911 | N16: =K16 -> 27743.32 | O16: =IFERROR(N16/$E$11,0) -> 3082.5911 | R16: 613 Main Street | S16: A1 | T16: 2/1.50 | U16: 850 | V16: 2995 | W16: =IF(T16="","",_xlfn.XLOOKUP(T16,$S$4:$S$10,$W$4:$W$10)) -> 2995 | X16: =IF(T16="*Insert Unit Type*","",_xlfn.XLOOKUP(T16,$S$4:$S$10,$X$4:$X$10,"")) -> 3200 | Y16: INSERT | Z16: INSERT
B17: Price/RSF | E17: =IFERROR(E14/E10,0) -> 410.8651 | G17: Property Insurance | H17: ='2025 P&L Given'!O15 -> 4320 | I17: =IFERROR(H17/$E$11,0) -> 480 | K17: =H17 -> 4320 | L17: =IFERROR(K17/$E$11,0) -> 480 | N17: =K17 -> 4320 | O17: =IFERROR(N17/$E$11,0) -> 480 | R17: 613 Main Street | S17: A2 | T17: 2/1.00 | U17: 950 | V17: 2875 | W17: =IF(T17="","",_xlfn.XLOOKUP(T17,$S$4:$S$10,$W$4:$W$10)) -> 2875 | X17: =IF(T17="*Insert Unit Type*","",_xlfn.XLOOKUP(T17,$S$4:$S$10,$X$4:$X$10,"")) -> 3100 | Y17: INSERT | Z17: INSERT
B18: Cap Rate - T12 | E18: =IFERROR(H26/E14,0) -> 0.061843522 | G18: Sewer | H18: ='2025 P&L Given'!O13 -> 4320 | I18: =IFERROR(H18/$E$11,0) -> 480 | K18: =H18 -> 4320 | L18: =IFERROR(K18/$E$11,0) -> 480 | N18: =K18 -> 4320 | O18: =IFERROR(N18/$E$11,0) -> 480 | R18: 613 Main Street | S18: A3 - Affordable | T18: 2/1.00 - 60% | U18: 650 | V18: 1534 | W18: =IF(T18="","",_xlfn.XLOOKUP(T18,$S$4:$S$10,$W$4:$W$10)) -> 1534 | X18: =IF(T18="*Insert Unit Type*","",_xlfn.XLOOKUP(T18,$S$4:$S$10,$X$4:$X$10,"")) -> 1935 | Y18: INSERT | Z18: INSERT
B19: Cap Rate - Current/Year 1 | E19: =K26/E14 -> 0.060317789 | G19: Water | H19: ='2025 P&L Given'!O14 -> 696 | I19: =IFERROR(H19/$E$11,0) -> 77.333333 | K19: =H19 -> 696 | L19: =IFERROR(K19/$E$11,0) -> 77.333333 | N19: =K19 -> 696 | O19: =IFERROR(N19/$E$11,0) -> 77.333333 | R19: 613 Main Street | S19: B1 | T19: 2/1.5 TH w. Garage | U19: 1052 | V19: 2895 | W19: =IF(T19="","",_xlfn.XLOOKUP(T19,$S$4:$S$10,$W$4:$W$10)) -> 3350 | X19: =IF(T19="*Insert Unit Type*","",_xlfn.XLOOKUP(T19,$S$4:$S$10,$X$4:$X$10,"")) -> 3350 | Y19: INSERT | Z19: INSERT
B20: Cap Rate - Pro Forma | E20: =N26/E14 -> 0.068886256 | G20: Trash Removal | H20: ='2025 P&L Given'!O18 -> 4380 | I20: =IFERROR(H20/$E$11,0) -> 486.66667 | K20: =H20 -> 4380 | L20: =IFERROR(K20/$E$11,0) -> 486.66667 | N20: =K20 -> 4380 | O20: =IFERROR(N20/$E$11,0) -> 486.66667 | R20: 613 Main Street | S20: B2 | T20: 2/1.5 TH w. Garage | U20: 1052 | V20: 2895 | W20: =IF(T20="","",_xlfn.XLOOKUP(T20,$S$4:$S$10,$W$4:$W$10)) -> 3350 | X20: =IF(T20="*Insert Unit Type*","",_xlfn.XLOOKUP(T20,$S$4:$S$10,$X$4:$X$10,"")) -> 3350 | Y20: INSERT | Z20: INSERT
B21: Cash-on-Cash - Current/Year 1 | E21: =K32 -> 0.031032347 | G21: Alarm Monitoring | H21: ='2025 P&L Given'!O19 -> 2376 | I21: =IFERROR(H21/$E$11,0) -> 264 | K21: =H21 -> 2376 | L21: =IFERROR(K21/$E$11,0) -> 264 | N21: =K21 -> 2376 | O21: =IFERROR(N21/$E$11,0) -> 264 | R21: 613 Main Street | S21: B3 | T21: 2/1.5 TH w. Garage | U21: 1052 | V21: 3350 | W21: =IF(T21="","",_xlfn.XLOOKUP(T21,$S$4:$S$10,$W$4:$W$10)) -> 3350 | X21: =IF(T21="*Insert Unit Type*","",_xlfn.XLOOKUP(T21,$S$4:$S$10,$X$4:$X$10,"")) -> 3350 | Y21: INSERT | Z21: INSERT
B22: Cash-on-Cash - Pro Forma | E22: =N32 -> 0.055168872 | G22: Landscaping | H22: ='2025 P&L Given'!O16 -> 5200 | I22: =IFERROR(H22/$E$11,0) -> 577.77778 | K22: 5200 | L22: =IFERROR(K22/$E$11,0) -> 577.77778 | N22: =K22 -> 5200 | O22: =IFERROR(N22/$E$11,0) -> 577.77778 | R22: 613 Main Street | S22: C1 - Affordable | T22: 2/1.5 TH w. Basement - 80% | U22: 1052 | V22: 2039 | W22: =IF(T22="","",_xlfn.XLOOKUP(T22,$S$4:$S$10,$W$4:$W$10)) -> 2039 | X22: =IF(T22="*Insert Unit Type*","",_xlfn.XLOOKUP(T22,$S$4:$S$10,$X$4:$X$10,"")) -> 2039 | Y22: INSERT | Z22: INSERT
B23: UYOC - Current/Year 1 | E23: =K33 -> 0.0600177 | G23: Snow Removal | H23: ='2025 P&L Given'!O17 -> 12140 | I23: =IFERROR(H23/$E$11,0) -> 1348.8889 | K23: 12140 | L23: =IFERROR(K23/$E$11,0) -> 1348.8889 | N23: =K23 -> 12140 | O23: =IFERROR(N23/$E$11,0) -> 1348.8889 | R23: 613 Main Street | S23: C2 - Affordable | T23: 2/1.5 TH w. Basement - 60% | U23: 1052 | V23: 1478 | W23: =IF(T23="","",_xlfn.XLOOKUP(T23,$S$4:$S$10,$W$4:$W$10)) -> 1478 | X23: =IF(T23="*Insert Unit Type*","",_xlfn.XLOOKUP(T23,$S$4:$S$10,$X$4:$X$10,"")) -> 1935 | Y23: INSERT | Z23: INSERT
B24: UYOC - Pro Forma | E24: =N33 -> 0.068543538 | G24: Total Expense | H24: =SUM(H16:H23) -> 61175.32 | I24: =SUM(I16:I23) -> 6797.2578 | J24: =IFERROR(H24/H12,0) -> 0.21554874 | K24: =SUM(K16:K23) -> 61175.32 | L24: =SUM(L16:L23) -> 6797.2578 | M24: =IFERROR(K24/K12,0) -> 0.2198026 | N24: =SUM(N16:N23) -> 61175.32 | O24: =SUM(O16:O23) -> 6797.2578 | P24: =IFERROR(N24/N12,0) -> 0.19787218 | R24: 613 Main Street | S24: C3 | T24: 2/1.5 TH w. Basement | U24: 1052 | V24: 2825 | W24: =IF(T24="","",_xlfn.XLOOKUP(T24,$S$4:$S$10,$W$4:$W$10)) -> 2825 | X24: =IF(T24="*Insert Unit Type*","",_xlfn.XLOOKUP(T24,$S$4:$S$10,$X$4:$X$10,"")) -> 3250 | Y24: INSERT | Z24: INSERT
B25: Average Rent - Current | E25: =V12 -> 2542.8889 | R25: Monthly Total | U25: =SUM(U16:U24) -> 8762 | V25: =SUM(V16:V24) -> 22886 | W25: =SUM(W16:W24) -> 23796 | X25: =SUM(X16:X24) -> 25509
B26: Average High Achieved Rent | E26: =W12 -> 2644 | G26: Net Operating Income | H26: =H12-H24 -> 222636.68 | K26: =K12-K24 -> 217144.04 | N26: =N12-N24 -> 247990.52
B27: Average Rent - Pro Forma | E27: =X12 -> 2834.3333
B28: Trade Range | G28: Debt Service | K28: =E40 -> 177484.7 | N28: =E40 -> 177484.7
B29: Cap Rate | C29: Price/Unit | D29: Price/SF | E29: Sales Price
B30: 0.055 | C30: =IFERROR(E30/$E$11,0) -> 438674.83 | D30: =IFERROR(E30/$E$10,0) -> 450.59044 | E30: =$K$26/B30 -> 3948073.5 | G30: Cashflow after Debt Service | K30: =K26-K28 -> 39659.339 | N30: =N26-N28 -> 70505.819
B31: =B30+0.25% -> 0.0575 | C31: =IFERROR(E31/$E$11,0) -> 419602.01 | D31: =IFERROR(E31/$E$10,0) -> 430.99955 | E31: =$K$26/B31 -> 3776418.1
B32: =B31+0.25% -> 0.06 | C32: =IFERROR(E32/$E$11,0) -> 402118.59 | D32: =IFERROR(E32/$E$10,0) -> 413.04124 | E32: =$K$26/B32 -> 3619067.3 | G32: Cash on Cash | K32: =K30/E51 -> 0.031032347 | N32: =N30/E51 -> 0.055168872
B33: =B32+0.25% -> 0.0625 | C33: =IFERROR(E33/$E$11,0) -> 386033.85 | D33: =IFERROR(E33/$E$10,0) -> 396.51959 | E33: =$K$26/B33 -> 3474304.6 | G33: UYOC | K33: =K26/E52 -> 0.0600177 | N33: =N26/E52 -> 0.068543538
B34: =B33+0.25% -> 0.065 | C34: =IFERROR(E34/$E$11,0) -> 371186.39 | D34: =IFERROR(E34/$E$10,0) -> 381.26884 | E34: =$K$26/B34 -> 3340677.5
B35: Debt Assumptions
B36: LTV Bound | E36: 0.65
B37: DSCR Bound | E37: 1.2
B38: Interest Rate | E38: 0.065
B39: Amortization (Years) | E39: 30
B40: Annual Debt Service | E40: =IFERROR(PMT(E38/12,E39*12,-(MIN(E36*E14,K26/E37/(PMT(E38/12,E39*12,-1)*12))),0)*12,0) -> 177484.7
B42: Down PMT | E42: =IFERROR(E14-E43,0) -> 1260000
...

Sheet 2025 P&L Given
A1: NORTHEAST PRIVATE CLIENT GROUP
A2: Profit & Loss Statement
A3: 613 Main Street, Ridgefield, CT | Trailing 12 Months
C6: Jan | D6: Feb | E6: Mar | F6: Apr | G6: May | H6: Jun | I6: Jul | J6: Aug | K6: Sep | L6: Oct | M6: Nov | N6: Dec | O6: Annual
A7: INCOME
B8: Rent | C8: 23000 | D8: 23000 | E8: 23000 | F8: 23000 | G8: 23000 | H8: 23000 | I8: 23000 | J8: 23000 | K8: 23000 | L8: 23000 | M8: 23000 | N8: 23000 | O8: =SUM(C8:N8) -> 276000
B9: RE Taxes | C9: -2311 | D9: -2311 | E9: -2311 | F9: -2311 | G9: -2311 | H9: -2311 | I9: -2311 | J9: -2311 | K9: -2311 | L9: -2311 | M9: -2311 | N9: -2311 | O9: =SUM(C9:N9) -> -27732
B10: Effective Gross Income | C10: =SUM(C8:C9) -> 20689 | D10: =SUM(D8:D9) -> 20689 | E10: =SUM(E8:E9) -> 20689 | F10: =SUM(F8:F9) -> 20689 | G10: =SUM(G8:G9) -> 20689 | H10: =SUM(H8:H9) -> 20689 | I10: =SUM(I8:I9) -> 20689 | J10: =SUM(J8:J9) -> 20689 | ... N10: =SUM(N8:N9) -> 20689 | O10: =SUM(C10:N10) -> 248268
A12: OPERATING EXPENSES
B13: Sewer | C13: 360 | D13: 360 | E13: 360 | F13: 360 | G13: 360 | H13: 360 | I13: 360 | J13: 360 | K13: 360 | L13: 360 | M13: 360 | N13: 360 | O13: =SUM(C13:N13) -> 4320
B14: Water | C14: 58 | D14: 58 | E14: 58 | F14: 58 | G14: 58 | H14: 58 | I14: 58 | J14: 58 | K14: 58 | L14: 58 | M14: 58 | N14: 58 | O14: =SUM(C14:N14) -> 696
B15: Insurance | C15: 360 | D15: 360 | E15: 360 | F15: 360 | G15: 360 | H15: 360 | I15: 360 | J15: 360 | K15: 360 | L15: 360 | M15: 360 | N15: 360 | O15: =SUM(C15:N15) -> 4320
B16: Lawn | F16: 650 | G16: 650 | H16: 650 | I16: 650 | J16: 650 | K16: 650 | L16: 650 | M16: 650 | O16: =SUM(C16:N16) -> 5200
B17: Snow | C17: 3180 | D17: 3180 | E17: 3180 | N17: 2600 | O17: =SUM(C17:N17) -> 12140
B18: Refuse | C18: 365 | D18: 365 | E18: 365 | F18: 365 | G18: 365 | H18: 365 | I18: 365 | J18: 365 | K18: 365 | L18: 365 | M18: 365 | N18: 365 | O18: =SUM(C18:N18) -> 4380
B19: Alarm | C19: 198 | D19: 198 | E19: 198 | F19: 198 | G19: 198 | H19: 198 | I19: 198 | J19: 198 | K19: 198 | L19: 198 | M19: 198 | N19: 198 | O19: =SUM(C19:N19) -> 2376
B20: Total Operating Expenses | C20: =SUM(C13:C19) -> 4521 | D20: =SUM(D13:D19) -> 4521 | E20: =SUM(E13:E19) -> 4521 | F20: =SUM(F13:F19) -> 1991 | G20: =SUM(G13:G19) -> 1991 | H20: =SUM(H13:H19) -> 1991 | I20: =SUM(I13:I19) -> 1991 | J20: =SUM(J13:J19) -> 1991 | ... N20: =SUM(N13:N19) -> 3941 | O20: =SUM(C20:N20) -> 33432
B21: NET OPERATING INCOME | C21: =C10-C20 -> 16168 | D21: =D10-D20 -> 16168 | E21: =E10-E20 -> 16168 | F21: =F10-F20 -> 18698 | G21: =G10-G20 -> 18698 | H21: =H10-H20 -> 18698 | I21: =I10-I20 -> 18698 | J21: =J10-J20 -> 18698 | ... N21: =N10-N20 -> 16748 | O21: =SUM(C21:N21) -> 214836

Sheet RR - Given
A1: NORTHEAST PRIVATE CLIENT GROUP
A2: Rent Roll
A3: 613 Main Street, Ridgefield, CT | As of 05/27/2026
B6: Tenant | C6: Unit Type | D6: Unit | E6: Classification | F6: Lease Start | G6: Lease End | H6: Rent Type | I6: Monthly Rent | J6: Annual Rent
B7: Edward McCarthy | C7: 2/1.50 | D7: 613 Main Street - A1 | E7: Market | F7: 45509 | G7: 46234 | H7: Fixed | I7: 2995 | J7: =I7*12 -> 35940
B8: Min Yang | C8: 2/1.00 | D8: 613 Main Street - A2 | E8: Market | F8: 45280 | G8: 46387 | H8: Fixed | I8: 2875 | J8: =I8*12 -> 34500
B9: Caroline Albano, Thomas Starkey | C9: 2/1.00 | D9: 613 Main Street - A3 | E9: Affordable | F9: 44986 | G9: 46446 | H9: Fixed | I9: 1534 | J9: =I9*12 -> 18408
B10: Robert Wright | C10: 2/1.5 TH w. Garage | D10: 613 Main Street - B1 | E10: Market | F10: 43258 | G10: 46538 | H10: Fixed | I10: 2895 | J10: =I10*12 -> 34740
B11: Nicholas Kiger | C11: 2/1.5 TH w. Garage | D11: 613 Main Street - B2 | E11: Market | F11: 43966 | G11: 46538 | H11: Fixed | I11: 2895 | J11: =I11*12 -> 34740
B12: Darrell Alfieri | C12: 2/1.5 TH w. Garage | D12: 613 Main Street - B3 | E12: Market | F12: 45872 | G12: 46234 | H12: Fixed | I12: 3350 | J12: =I12*12 -> 40200
B13: Sherrie Ellis | C13: 2/1.5 TH w. Basement | D13: 613 Main Street - C1 | E13: Affordable | F13: 42919 | G13: 46203 | H13: Fixed | I13: 2039 | J13: =I13*12 -> 24468
B14: Daniel McGerald | C14: 2/1.5 TH w. Basement | D14: 613 Main Street - C2 | E14: Affordable | F14: 43405 | G14: 46507 | H14: Fixed | I14: 1478 | J14: =I14*12 -> 17736
B15: Mary Hafter | C15: 2/1.5 TH w. Basement | D15: 613 Main Street - C3 | E15: Market | F15: 45108 | G15: 46568 | H15: Fixed | I15: 2825 | J15: =I15*12 -> 33900
B16: Subtotal — Base Rent | I16: =SUM(I7:I15) -> 22886 | J16: =SUM(J7:J15) -> 274632
B17: Utility Fee | I17: 765 | J17: =I17*12 -> 9180
B18: TOTAL GROSS RENT | I18: =I16+I17 -> 23651 | J18: =J16+J17 -> 283812
A21: UNIT MIX SUMMARY
B22: Classification | C22: Unit Count | D22: Monthly Rent | E22: Avg Rent / Unit
B23: Market Units | C23: =COUNTIF(E7:E15,"Market") -> 6 | D23: =SUMIF(E7:E15,"Market",I7:I15) -> 17835 | E23: =IFERROR(AVERAGEIF(E7:E15,"Market",I7:I15),0) -> 2972.5
B24: Affordable Units | C24: =COUNTIF(E7:E15,"Affordable") -> 3 | D24: =SUMIF(E7:E15,"Affordable",I7:I15) -> 5051 | E24: =IFERROR(AVERAGEIF(E7:E15,"Affordable",I7:I15),0) -> 1683.6667
B25: Total | C25: =C23+C24 -> 9 | D25: =D23+D24 -> 22886 | E25: =IFERROR(D25/C25,0) -> 2542.8889
B27: Highlighted rows = Affordable units
B28: Source: Owner-provided lease export, 05/27/2026

Sheet Tax Analysis
A1: NORTHEAST PRIVATE CLIENT GROUP
A2: Real Estate Tax Analysis
A3: 613 Main Street, Ridgefield, CT | Town of Ridgefield
A6: TAX BILL COMPARISON (2-YEAR)
C7: FY2024 Bill | D7: FY2025 Bill | E7: Δ ($) | F7: Δ (%)
B8: Grand List Year | C8: 2023 GL | D8: 2024 GL | E8: — | F8: —
B9: Bill Year | C9: 2024 | D9: 2025 | E9: — | F9: —
B10: Mill Rate | C10: 26.35 | D10: 27.39 | E10: =D10-C10 -> 1.04 | F10: =(D10-C10)/C10 -> 0.039468691
B11: Gross Assessment | C11: 1012900 | D11: 1012900 | E11: =D11-C11 -> 0 | F11: =IF(C11=0,0,(D11-C11)/C11) -> 0
B12: Exemption | C12: 0 | D12: 0 | E12: =D12-C12 -> 0
B13: Net Assessment | C13: 1012900 | D13: 1012900 | E13: =D13-C13 -> 0 | F13: =IF(C13=0,0,(D13-C13)/C13) -> 0
B14: Total Tax Due | C14: 26689.92 | D14: 27743.32 | E14: =D14-C14 -> 1053.4 | F14: =(D14-C14)/C14 -> 0.039468084
B15: Quarterly Payment | C15: =C14/4 -> 6672.48 | D15: =D14/4 -> 6935.83 | E15: =D15-C15 -> 263.35 | F15: =(D15-C15)/C15 -> 0.039468084
A17: IMPLIED MARKET VALUATION (CT 70% RATIO)
B18: Net Assessment (FY25) | C18: =D13 -> 1012900 | D18: Per tax bill
B19: CT Assessment Ratio | C19: 0.7 | D19: CGS §12-62a
B20: Implied Fair Market Value | C20: =C18/C19 -> 1447000 | D20: Assessment ÷ ratio
B21: Per-Unit Implied Value | C21: =C20/9 -> 160777.78 | D21: 9 units
A23: TAX BURDEN & ESCROW ANALYSIS
B24: Annual Tax Liability (FY25) | C24: =D14 -> 27743.32 | D24: Per tax bill
B25: Monthly Tax Escrow | C25: =C24/12 -> 2311.9433 | D25: Recommended reserve
B26: P&L Reported Monthly Tax | C26: 2311 | D26: From owner P&L
B27: Variance vs Actual (Monthly) | C27: =C26-C25 -> -0.94333333 | D27: Positive = underfunded
B28: Annual Gross Rent | C28: ='[1]P&L'!O8 -> 276000 | D28: From P&L
B29: Tax as % of Gross Rent | C29: =C24/C28 -> 0.10051928 | D29: Higher = more tax-burdened | G29: `
B30: Tax per Unit (Annual) | C30: =C24/9 -> 3082.5911 | D30: 9 units
A33: NOTES & SOURCES
B34: • Ridgefield, CT operates on July 1 – June 30 fiscal year; tax bills issued July, payable quarterly (Jul/Oct/Jan/Apr).
B35: • Mill rate increased from 26.35 to 27.39 (+3.9%); assessment held flat year-over-year.
B36: • Connecticut statute (CGS §12-62a) mandates assessments at 70% of fair market value.
B37: • Next municipal revaluation may adjust assessed value upward — model sensitivity in projections.
B38: • Sources: Town of Ridgefield Real Estate Tax Bills, 2023 GL and 2024 GL.

Sheet Sheet4
A1: NORTHEAST PRIVATE CLIENT GROUP
A2: Affordability Analysis
A3: 613 Main Street, Ridgefield, CT | 8-30g Set-Aside Restrictions
A6: DEED RESTRICTION SUMMARY (PER OWNER)
B7: Restriction Source | C7: CGS §8-30g — Set-Aside Development
B8: Required Affordable % | C8: 30% of units (3 of 9)
B9: Income Tier Breakdown | C9: 2 units @ 60% of SMI/AMI (lesser) | 1 unit @ 80% of SMI/AMI (lesser)
B10: Governing Standard | C10: Lesser of CT State Median Income (SMI) or Stamford-Norwalk HUD AMI
B11: Practical Result | C11: SMI has always been lower — SMI controls
B12: Restriction Term | C12: 40 years (per CGS §8-30g)
A14: INCOME BASIS: SMI vs. AMI (2025, 4-PERSON HH)
B15: Standard | C15: 100% (4P) | D15: 80% (4P) | E15: 60% (4P) | F15: Notes
B16: CT State Median Income (SMI) | C16: 91665 | D16: =C16*0.8 -> 73332 | E16: =C16*0.6 -> 54999 | F16: Source: HUD FY2025 / UCONN CLEAR
B17: Stamford-Norwalk HUD AMI | C17: 180500 | D17: =C17*0.8 -> 144400 | E17: =C17*0.6 -> 108300 | F17: Source: Stamford 2025 BMR schedule
B18: Delta (AMI - SMI) | C18: =C17-C16 -> 88835 | D18: =D17-D16 -> 71068 | E18: =E17-E16 -> 53301 | F18: AMI is materially higher
B19: Delta % | C19: =(C17-C16)/C16 -> 0.96912671 | D19: =(D17-D16)/D16 -> 0.96912671 | E19: =(E17-E16)/E16 -> 0.96912671 | F19: AMI ~97% higher than SMI
A22: MAX GROSS RENT BY BEDROOM - CURRENT 8-30g (SMI BASIS)
B23: Bedroom Size | C23: Assumed HH | D23: 80% SMI Rent | E23: 60% SMI Rent | F23: Source
B24: Studio | C24: 1 | D24: =$C$16*0.7*0.8*0.3/12 -> 1283.31 | E24: =$C$16*0.7*0.6*0.3/12 -> 962.4825 | F24: 1P factor 0.70
B25: 1 Bedroom | C25: 1.5 | D25: =$C$16*0.75*0.8*0.3/12 -> 1374.975 | E25: =$C$16*0.75*0.6*0.3/12 -> 1031.2313 | F25: Avg 1P/2P = 0.75
B26: 2 Bedroom | C26: 3 | D26: =$C$16*0.9*0.8*0.3/12 -> 1649.97 | E26: =$C$16*0.9*0.6*0.3/12 -> 1237.4775 | F26: 3P factor 0.90
B27: 3 Bedroom | C27: 4.5 | D27: =$C$16*1.04*0.8*0.3/12 -> 1906.632 | E27: =$C$16*1.04*0.6*0.3/12 -> 1429.974 | F27: Avg 4P/5P = 1.04
B28: Rent = 30% x Income / 12. HUD HH-size factors: 1P=0.70, 2P=0.80, 3P=0.90, 4P=1.00, 5P=1.08
A30: MAX GROSS RENT BY BEDROOM - STAMFORD-NORWALK AMI (NEW TOWN REG)
B31: Bedroom Size | C31: 80% AMI Rent | D31: 60% AMI Rent | E31: 50% AMI Rent | F31: Source
B32: Studio | C32: 1706 | D32: 1421 | E32: 1218 | F32: Stamford 2025 BMR schedule
B33: 1 Bedroom | C33: 2031 | D33: 1692 | E33: 1408
B34: 2 Bedroom | C34: 2437 | D34: 2031 | E34: 1521 | F34: Owner-cited ~$2.5K confirmed
B35: 3 Bedroom | C35: 2816 | D35: 2347 | E35: 1758
B36: Note: New town inclusionary reg applies to NEW developments only. Existing 8-30g restrictions retain SMI basis until release.
A38: CURRENT AFFORDABLE UNIT ANALYSIS - GAP TO MARKET
B39: Unit | C39: Current Rent | D39: Mkt Comp | E39: Gap to Market | F39: Annual Gap | G39: Notes
B40: A3 (Albano/Starkey) | C40: 1534 | D40: 2895 | E40: =D40-C40 -> 1361 | F40: =E40*12 -> 16332 | G40: 60% tier
B41: C1 (Sherrie Ellis) | C41: 2039 | D41: 2895 | E41: =D41-C41 -> 856 | F41: =E41*12 -> 10272 | G41: 80% tier
B42: C2 (Daniel McGerald) | C42: 1478 | D42: 2895 | E42: =D42-C42 -> 1417 | F42: =E42*12 -> 17004 | G42: 60% tier
B43: TOTAL | C43: =SUM(C40:C42) -> 5051 | D43: =SUM(D40:D42) -> 8685 | E43: =SUM(E40:E42) -> 3634 | F43: =SUM(F40:F42) -> 43608 | G43: 3 of 9 units
A45: STABILIZED RENT SCENARIOS
B46: Scenario | C46: Affordable Rent Basis | D46: Annual Gross Rent | E46: Delta vs Current | F46: Implied NOI
B47: Current (As-Is) | C47: Per existing leases | D47: 282792 | E47: 0 | F47: =D47-'[2]P&L'!O20+'[2]P&L'!O9 -> 221628
B48: Mark Affordables to 80% SMI | C48: All 3 ~ $1,650 | D48: =12*(1650*3) + 6*2895*12 + 765*12 -> 277020 | E48: =D48-D47 -> -5772 | F48: =D48-'[2]P&L'!O20+'[2]P&L'!O9 -> 215856
...
