Workbook

Sheet Current
A1: Address: | B1: 20 Hysil Ave, Chelsea
A2: Unit Count: | B2: 16
A3: Rentable SF: | B3: 14478 | D3: =B3/16 -> 904.875
B5: Unit | C5: Income | D5: Bed Type | E5: SF | F5: Per SF | G5: Notes | H5: Pro Forma | I5: Per SF | K5: Expenses | L5: Current | M5: Per Unit | N5: Pro Forma | O5: Per Unit | P5: Notes | R5: Mortgage Calculator
B6: 1 | C6: 2475 | D6: 2 Bed | E6: 900 | F6: =C6/E6 -> 2.75 | G6: VACANT-Unrented | H6: 2550 | I6: =H6/E6 -> 2.8333333 | K6: Taxes (7&20) | L6: =41871.27+1016 -> 42887.27 | M6: =L6/16 -> 2680.4544 | N6: =L6 -> 42887.27 | O6: =N6/16 -> 2680.4544 | R6: Loan Amount | S6: =T6*B36 -> 3000000 | T6: =1-C43 -> 0.75
B7: 2 | C7: 1850 | D7: 1 Bed | E7: 700 | F7: =C7/E7 -> 2.6428571 | H7: 2050 | I7: =H7/E7 -> 2.9285714 | K7: Insurance | L7: 18898.51 | M7: =L7/16 -> 1181.1569 | N7: 16000 | O7: =N7/16 -> 1000 | R7: Annual Interest Rate | S7: 0.065
B8: 3 | C8: 1700 | D8: 1 Bed | E8: 700 | F8: =C8/E8 -> 2.4285714 | H8: 2050 | I8: =H8/E8 -> 2.9285714 | K8: Water & Sewer | L8: =7847.06+11436.18 -> 19283.24 | M8: =L8/16 -> 1205.2025 | N8: =L8 -> 19283.24 | O8: =N8/16 -> 1205.2025 | R8: Life Loan (in years) | S8: 30
B9: 4 | C9: 1950 | D9: 1 Bed | E9: 700 | F9: =C9/E9 -> 2.7857143 | H9: 2050 | I9: =H9/E9 -> 2.9285714 | K9: Electric | L9: 3109.52 | M9: =L9/16 -> 194.345 | N9: =L9 -> 3109.52 | O9: =N9/16 -> 194.345 | P9: tenant paid | R9: Number of Payments per year | S9: 12
B10: 5 | C10: 2450 | D10: 2 Bed | E10: 900 | F10: =C10/E10 -> 2.7222222 | H10: 2550 | I10: =H10/E10 -> 2.8333333 | K10: Gas | L10: 0 | M10: =L10/16 -> 0 | N10: =L10 -> 0 | O10: =N10/16 -> 0 | P10: NONE | R10: Total Number of Payments | S10: =S8*S9 -> 360
B11: 6 | C11: 1900 | D11: 1 Bed | E11: 700 | F11: =C11/E11 -> 2.7142857 | H11: 2050 | I11: =H11/E11 -> 2.9285714 | K11: Repairs & Maintenance | L11: =B2*500 -> 8000 | M11: =L11/16 -> 500 | N11: =L11 -> 8000 | O11: =N11/16 -> 500 | R11: Payment per Period | S11: =-PMT(S7/S9,S10,S6) -> 18962.041
B12: 7 | C12: 2950 | D12: 3 Bed | E12: 1100 | F12: =C12/E12 -> 2.6818182 | H12: 3050 | I12: =H12/E12 -> 2.7727273 | K12: Snow & Landscape | L12: 4000 | M12: =L12/16 -> 250 | N12: =L12 -> 4000 | O12: =N12/16 -> 250 | R12: Sum of Payments | S12: =S10*S11 -> 6826334.7
B13: 8 | C13: 1850 | D13: 1 Bed | E13: 700 | F13: =C13/E13 -> 2.6428571 | H13: 2050 | I13: =H13/E13 -> 2.9285714 | K13: Management Fees (4%) | L13: =B28*0.04 -> 16470.6 | M13: =L13/16 -> 1029.4125 | N13: =H28*0.04 -> 17418.24 | O13: =N13/16 -> 1088.64 | R13: Interest Cost | S13: =S6-S12 -> -3826334.7
B14: 9 | C14: 2850 | D14: 3 Bed | E14: 1100 | F14: =C14/E14 -> 2.5909091 | H14: 3050 | I14: =H14/E14 -> 2.7727273 | K14: Trash Removal (Estimated) | L14: 6000 | M14: =L14/16 -> 375 | N14: =L14 -> 6000 | O14: =N14/16 -> 375 | P14: high
B15: 10 | C15: 1800 | D15: 1 Bed | E15: 700 | F15: =C15/E15 -> 2.5714286 | H15: 2050 | I15: =H15/E15 -> 2.9285714 | K15: Internet / Security | L15: 3101.76 | M15: =L15/16 -> 193.86 | N15: =L15 -> 3101.76 | O15: =N15/16 -> 193.86 | R15: DCR | S15: =B34/(S11*12) -> 1.268498
B16: 11 | C16: 2950 | D16: 3 Bed | E16: 1100 | F16: =C16/E16 -> 2.6818182 | G16: VACANT-Unrented | H16: 3050 | I16: =H16/E16 -> 2.7727273 | K16: Fire Alarm | L16: 0 | M16: =L16/16 -> 0 | N16: =L16 -> 0 | O16: =N16/16 -> 0
B17: 12 | C17: 1800 | D17: 1 Bed | E17: 700 | F17: =C17/E17 -> 2.5714286 | H17: 2050 | I17: =H17/E17 -> 2.9285714 | K17: Cleaning / Pest Control | L17: =3650+1026.38 -> 4676.38 | M17: =L17/16 -> 292.27375 | N17: =L17 -> 4676.38 | O17: =N17/16 -> 292.27375
B18: 14 | C18: 2500 | D18: 2 Bed | E18: 900 | F18: =C18/E18 -> 2.7777778 | H18: 2550 | I18: =H18/E18 -> 2.8333333 | K18: Total Expenses: | L18: =SUM(L6:L17) -> 126427.28 | M18: =L18/16 -> 7901.705 | N18: =SUM(N6:N17) -> 124476.41 | O18: =N18/16 -> 7779.7756 | R18: Pro- Forma / Refi Mortgage Calculator
B19: 15 | C19: 1850 | D19: 1 Bed | E19: 700 | F19: =C19/E19 -> 2.6428571 | H19: 2050 | I19: =H19/E19 -> 2.9285714 | R19: Loan Amount | S19: =T19*H36 -> 3000000 | T19: =1-I43 -> 0.75
B20: 16 | C20: 2400 | D20: 2 Bed | E20: 900 | F20: =C20/E20 -> 2.6666667 | H20: 2550 | I20: =H20/E20 -> 2.8333333 | K20: Expense Ratio | L20: =L18/B28 -> 0.30703746 | N20: =N18/H28 -> 0.28585301 | R20: Annual Interest Rate | S20: 0.065
B21: 17 | C21: 2100 | D21: 1 Bed | E21: 700 | F21: =C21/E21 -> 3 | H21: 2050 | I21: =H21/E21 -> 2.9285714 | K21: Per Unit | L21: =L18/B2 -> 7901.705 | N21: =N18/B2 -> 7779.7756 | R21: Life Loan (in years) | S21: 30
B22: Monthly | C22: =SUM(C6:C21) -> 35375 | E22: =SUM(E6:E21) -> 13200 | H22: =SUM(H6:H21) -> 37800 | R22: Number of Payments per year | S22: 12
B23: Yearly | C23: =C22*12 -> 424500 | H23: =H22*12 -> 453600 | R23: Total Number of Payments | S23: =S21*S22 -> 360
R24: Payment per Period | S24: =-PMT(S20/S22,S23,S19) -> 18962.041
K25: 7 | L25: 84400 | R25: Sum of Payments | S25: =S23*S24 -> 6826334.7
A26: GOI | B26: =C23 -> 424500 | H26: =H23 -> 453600 | K26: 20 | L26: 3415800 | R26: Interest Cost | S26: =S19-S25 -> -3826334.7
A27: Vacancy | B27: =B26*C27 -> -12735 | C27: -0.03 | H27: =H26*I27 -> -18144 | I27: -0.04 | K27: assessed | L27: =SUM(L25:L26) -> 3500200 | M27: reassessed | N27: =H36*0.8 -> 3200000
A28: GOI (vacancy) | B28: =SUM(B26:B27) -> 411765 | H28: =SUM(H26:H27) -> 435456 | L28: =L27/1000 -> 3500.2 | N28: =N27/1000 -> 3200 | R28: DCR | S28: =H34/(S24*12) -> 1.3811874
A29: Laundry | B29: 3302 | C29: coin-op | H29: =B29 -> 3302 | L29: =L28*11.48 -> 40182.296 | N29: =N28*11.48 -> 36736
A30: Cell Tower | B30: 0 | H30: =B30 -> 0
A31: Gross Effective | B31: =SUM(B28:B29) -> 415067 | H31: =SUM(H28:H29) -> 438758
A33: Total Expenses: | B33: =L18 -> 126427.28 | H33: =N18 -> 124476.41 | L33: paid $4.21mil in 2022
A34: NOI | B34: =B31-B33 -> 288639.72 | H34: =H31-H33 -> 314281.59
A35: Cap Rate | B35: =B34/B36 -> 0.07215993 | D35: Cap Rate | E35: Price | F35: Price Per Unit | G35: Pro Forma Cap Rate | H35: =H34/H36 -> 0.078570397
A36: List Price | B36: 4000000 | D36: 0.06 | E36: =B34/D36 -> 4810662 | F36: =E36/12 -> 400888.5 | G36: =H34/E36 -> 0.065330217 | H36: =B36 -> 4000000
A37: Per Unit | B37: =B36/B2 -> 250000 | D37: 0.0625 | E37: =B34/D37 -> 4618235.5 | F37: =E37/12 -> 384852.96 | G37: =H34/E37 -> 0.068052309 | H37: =H36/B2 -> 250000
A38: Per SF | B38: =B36/B3 -> 276.28125 | D38: 0.065 | E38: =B34/D38 -> 4440611.1 | F38: =E38/12 -> 370050.92 | G38: =H34/E38 -> 0.070774401 | H38: =H36/E22 -> 303.0303
D39: 0.0675 | E39: =B34/D39 -> 4276144 | F39: =E39/12 -> 356345.33 | G39: =H34/E39 -> 0.073496494
A40: Mortgage | B40: =S11*12 -> 227544.49 | D40: 0.07 | E40: =B34/D40 -> 4123424.6 | F40: =E40/12 -> 343618.71 | G40: =H34/E40 -> 0.076218586 | H40: =S24*12 -> 227544.49
A41: Cash Flow | B41: =B34-B40 -> 61095.232 | H41: =H34-H40 -> 86737.102
A42: Cash on Cash | B42: =B41/B43 -> 0.061095232 | H42: =H41/H43 -> 0.086737102
...

Sheet Financial Summary
E3: Current | F3: Pro Forma
B4: Income Summary | C4: Price | E4: =Current!B36 -> 4000000 | F4: =E4 -> 4000000
C5: Price/Unit | E5: =E4/Current!B2 -> 250000 | F5: =E5 -> 250000
C6: GRM | E6: =E4/E11 -> 9.4228504 | F6: =F4/F11 -> 8.8183422
C7: CAP Rate | E7: =E17/E4 -> 0.07215993 | F7: =F17/F4 -> 0.078570397
C8: Cash-on-Cash Return | E8: =E24/E19 -> 0.061095232 | F8: =F24/F19 -> 0.086737102
C9: Debt Coverage Ratio | E9: =E17/E22 -> 1.268498 | F9: =F17/F22 -> 1.3811874
B11: Operating Data | C11: Gross Scheduled Income | E11: =Current!B26 -> 424500 | F11: =Current!H26 -> 453600
C12: Other Income | E12: =SUM(Current!B29:B29) -> 3302 | F12: =SUM(Current!H29:H29) -> 3302
C13: Total Scheduled Income | E13: =E11+E12 -> 427802 | F13: =F11+F12 -> 456902
C14: Vacancy Cost | E14: =Current!B27 -> -12735 | F14: =Current!H27 -> -18144
C15: Gross Income | E15: =E13+E14 -> 415067 | F15: =F13+F14 -> 438758
C16: Operating Expenses | E16: =-Current!L18 -> -126427.28 | F16: =-Current!N18 -> -124476.41
C17: Net Operating Income | E17: =E15+E16 -> 288639.72 | F17: =F15+F16 -> 314281.59
B19: Financing Data | C19: Down Payment | E19: =Current!B43 -> 1000000 | F19: =Current!H43 -> 1000000
C20: Loan Amount | E20: =Current!S6 -> 3000000 | F20: =E20 -> 3000000
C21: Interest Rate (Estimate) | E21: =Current!S7 -> 0.065 | F21: =E21 -> 0.065
C22: Debt Service | E22: =Current!B40 -> 227544.49 | F22: =F23*12 -> 227544.49
C23: Debt Service Monthly | E23: =Current!S11 -> 18962.041 | F23: =E23 -> 18962.041
C24: Pre-Tax Cash Flow | E24: =E17-E22 -> 61095.232 | F24: =F17-F22 -> 86737.102
B26: ** Loan information is for illustrative purposes and is subject to change. Please conduct your own independent review
